Workbook

Sheet CA
A1: 管道吊架分组 | B1: 组件 | C1: 组件方向 | D1: 模态方向 | E1: 试验结果 | F1: 模拟结果 | G1: 差距百分比 | H1: 计算结果 | I1: 差距百分比 | J1: 摆长 | K1: 单摆结果 | L1: 差距百分比 | M1: m(kg) | N1: l(m) | O1: r | P1: k_θ_radial_cor | Q1: k_θ_axial_cor | S1: 回归结果
A2: 管夹横担/CA | B2: CA_07 | C2: A | D2: 径向平动 | E2: 0.6913 | F2: 0.73354 | G2: =(F2-E2)/E2 -> 0.061102271 | H2: =[1]test_program!$P$19 -> 0.69851249 | I2: =(H2-E2)/E2 -> 0.010433233 | J2: =N2*1000 -> 739 | K2: =1/2/PI()*SQRT(9.8*1000/J2) -> 0.57957674 | L2: =(K2-E2)/E2 -> -0.16161327 | M2: 488.2 | N2: 0.739 | O2: 0.008 | P2: =((E2*2*PI())^2-9.8/N2)/4*N2^2*M2 -> 373.62284 | R2: =$A$31*M2*9.8*O2*(N2/O2)^$A$33 -> 417.3511 | S2: =SQRT(4*R2/N2^2/M2+9.8/(N2))/2/PI() -> 0.70321659
A3: m(kg)_radial | D3: 轴向平动 | E3: 0.6913 | F3: 0.73318 | G3: =(F3-E3)/E3 -> 0.060581513 | H3: =[1]test_program!$P$19 -> 0.69851249 | I3: =(H3-E3)/E3 -> 0.010433233 | J3: =N3*1000 -> 739 | K3: =1/2/PI()*SQRT(9.8*1000/J3) -> 0.57957674 | L3: =(K3-E3)/E3 -> -0.16161327 | M3: 488.2 | N3: 0.739 | O3: 0.008 | Q3: =((E3*2*PI())^2-9.8/N3)/4*N3^2*M3 -> 373.62284 | R3: =$A$41*M3*9.8*O3*(N3/O3)^$A$43 -> 417.3511 | S3: =SQRT(4*R3/N3^2/M3+9.8/(N3))/2/PI() -> 0.70321659
A4: 3.2495 | D4: 平面转动 | E4: 0.7888 | F4: 0.85607 | G4: =(F4-E4)/E4 -> 0.08528144 | H4: =SQRT(H3^2*488/(256.85+1.62*50.1)*0.9^2) -> 0.7553714 | I4: =(H4-E4)/E4 -> -0.042379052 | K4: =SQRT(K3^2*488/(256.85+1.62*50.1)*0.9^2) -> 0.62675428 | L4: =(K4-E4)/E4 -> -0.20543321 | M4: 488.2 | N4: 0.739
A5: l(m)_radial | C5: R | D5: 径向平动 | E5: 0.6912 | F5: 0.73354 | G5: =(F5-E5)/E5 -> 0.061255787 | H5: =[1]test_program!$P$19 -> 0.69851249 | I5: =(H5-E5)/E5 -> 0.010579418 | J5: =N5*1000 -> 739 | K5: =1/2/PI()*SQRT(9.8*1000/J5) -> 0.57957674 | L5: =(K5-E5)/E5 -> -0.16149198 | M5: 488.2 | N5: 0.739 | O5: 0.008 | P5: =((E5*2*PI())^2-9.8/N5)/4*N5^2*M5 -> 373.25905 | R5: =$A$31*M5*9.8*O5*(N5/O5)^$A$33 -> 417.3511 | S5: =SQRT(4*R5/N5^2/M5+9.8/(N5))/2/PI() -> 0.70321659
A6: -1217.3254 | D6: 轴向平动 | E6: 0.6912 | F6: 0.73318 | G6: =(F6-E6)/E6 -> 0.060734954 | H6: =[1]test_program!$P$19 -> 0.69851249 | I6: =(H6-E6)/E6 -> 0.010579418 | J6: =N6*1000 -> 739 | K6: =1/2/PI()*SQRT(9.8*1000/J6) -> 0.57957674 | L6: =(K6-E6)/E6 -> -0.16149198 | M6: 488.2 | N6: 0.739 | O6: 0.008 | Q6: =((E6*2*PI())^2-9.8/N6)/4*N6^2*M6 -> 373.25905 | R6: =$A$41*M6*9.8*O6*(N6/O6)^$A$43 -> 417.3511 | S6: =SQRT(4*R6/N6^2/M6+9.8/(N6))/2/PI() -> 0.70321659
A7: c_radial | D7: 平面转动 | E7: 0.801 | F7: 0.85607 | G7: =(F7-E7)/E7 -> 0.068751561 | H7: =SQRT(H6^2*488/(256.85+1.62*50.1)*0.9^2) -> 0.7553714 | I7: =(H7-E7)/E7 -> -0.05696454 | K7: =SQRT(K6^2*488/(256.85+1.62*50.1)*0.9^2) -> 0.62675428 | L7: =(K7-E7)/E7 -> -0.21753523 | M7: 488.2 | N7: 0.739
A8: 0.0125 | B8: CA_13 | C8: A | D8: 径向平动 | E8: 0.4831 | F8: 0.49487 | G8: =(F8-E8)/E8 -> 0.024363486 | H8: =[1]test_program!$P$20 -> 0.48134388 | I8: =(H8-E8)/E8 -> -0.0036350967 | J8: =N8*1000 -> 1339 | K8: =1/2/PI()*SQRT(9.8*1000/J8) -> 0.43056912 | L8: =(K8-E8)/E8 -> -0.10873707 | M8: 488.2 | N8: 1.339 | O8: 0.008 | P8: =((E8*2*PI())^2-9.8/N8)/4*N8^2*M8 -> 414.63149 | R8: =$A$31*M8*9.8*O8*(N8/O8)^$A$33 -> 346.33665 | S8: =SQRT(4*R8/N8^2/M8+9.8/(N8))/2/PI() -> 0.47484746
A9: ml | D9: 轴向平动 | E9: 0.4831 | F9: 0.49486 | G9: =(F9-E9)/E9 -> 0.024342786 | H9: =[1]test_program!$P$20 -> 0.48134388 | I9: =(H9-E9)/E9 -> -0.0036350967 | J9: =N9*1000 -> 1339 | K9: =1/2/PI()*SQRT(9.8*1000/J9) -> 0.43056912 | L9: =(K9-E9)/E9 -> -0.10873707 | M9: 488.2 | N9: 1.339 | O9: 0.008 | Q9: =((E9*2*PI())^2-9.8/N9)/4*N9^2*M9 -> 414.63149 | R9: =$A$41*M9*9.8*O9*(N9/O9)^$A$43 -> 346.33665 | S9: =SQRT(4*R9/N9^2/M9+9.8/(N9))/2/PI() -> 0.47484746
A10: 3.7577 | D10: 平面转动 | E10: 0.5939 | F10: 0.57654 | G10: =(F10-E10)/E10 -> -0.02923051 | H10: =SQRT(H9^2*488/(256.85+1.62*50.1)*0.9^2) -> 0.52052527 | I10: =(H10-E10)/E10 -> -0.12354728 | K10: =SQRT(K9^2*488/(256.85+1.62*50.1)*0.9^2) -> 0.46561744 | L10: =(K10-E10)/E10 -> -0.21600026 | M10: 488.2 | N10: 1.339
A11: m2 | C11: R | D11: 径向平动 | E11: 0.473 | F11: 0.4671 | G11: =(F11-E11)/E11 -> -0.012473573 | H11: =[1]test_program!$P$20 -> 0.48134388 | I11: =(H11-E11)/E11 -> 0.017640348 | J11: =N11*1000 -> 1339 | K11: =1/2/PI()*SQRT(9.8*1000/J11) -> 0.43056912 | L11: =(K11-E11)/E11 -> -0.089705874 | M11: 488.2 | N11: 1.339 | O11: 0.008 | P11: =((E11*2*PI())^2-9.8/N11)/4*N11^2*M11 -> 331.20896 | R11: =$A$31*M11*9.8*O11*(N11/O11)^$A$33 -> 346.33665 | S11: =SQRT(4*R11/N11^2/M11+9.8/(N11))/2/PI() -> 0.47484746
A12: -0.0063 | D12: 轴向平动 | E12: 0.473 | F12: 0.46696 | G12: =(F12-E12)/E12 -> -0.012769556 | H12: =[1]test_program!$P$20 -> 0.48134388 | I12: =(H12-E12)/E12 -> 0.017640348 | J12: =N12*1000 -> 1339 | K12: =1/2/PI()*SQRT(9.8*1000/J12) -> 0.43056912 | L12: =(K12-E12)/E12 -> -0.089705874 | M12: 488.2 | N12: 1.339 | O12: 0.008 | Q12: =((E12*2*PI())^2-9.8/N12)/4*N12^2*M12 -> 331.20896 | R12: =$A$41*M12*9.8*O12*(N12/O12)^$A$43 -> 346.33665 | S12: =SQRT(4*R12/N12^2/M12+9.8/(N12))/2/PI() -> 0.47484746
A13: l2 | D13: 平面转动 | E13: 0.549 | F13: 0.5767 | G13: =(F13-E13)/E13 -> 0.050455373 | H13: =SQRT(H12^2*488/(256.85+1.62*50.1)*0.9^2) -> 0.52052527 | I13: =(H13-E13)/E13 -> -0.051866536 | K13: =SQRT(K12^2*488/(256.85+1.62*50.1)*0.9^2) -> 0.46561744 | L13: =(K13-E13)/E13 -> -0.15188079 | M13: 488.2 | N13: 1.339
A14: -297.4289 | B14: CA_07_Top | C14: A | D14: 径向平动 | E14: 0.5791 | F14: 0.56828 | G14: =(F14-E14)/E14 -> -0.018684165 | H14: =[1]test_program!$P$21 -> 0.56696172 | I14: =(H14-E14)/E14 -> -0.020960591 | J14: =N14*1000 -> 999 | K14: =1/2/PI()*SQRT(9.8*1000/J14) -> 0.49848308 | L14: =(K14-E14)/E14 -> -0.1392107 | M14: 556.6 | N14: 0.999 | O14: 0.008 | P14: =((E14*2*PI())^2-9.8/N14)/4*N14^2*M14 -> 476.26741 | R14: =$A$31*M14*9.8*O14*(N14/O14)^$A$33 -> 432.87646 | S14: =SQRT(4*R14/N14^2/M14+9.8/(N14))/2/PI() -> 0.57222572
D15: 轴向平动 | E15: 0.5791 | F15: 0.57217 | G15: =(F15-E15)/E15 -> -0.011966845 | H15: =[1]test_program!$P$21 -> 0.56696172 | I15: =(H15-E15)/E15 -> -0.020960591 | J15: =N15*1000 -> 999 | K15: =1/2/PI()*SQRT(9.8*1000/J15) -> 0.49848308 | L15: =(K15-E15)/E15 -> -0.1392107 | M15: 556.6 | N15: 0.999 | O15: 0.008 | Q15: =((E15*2*PI())^2-9.8/N15)/4*N15^2*M15 -> 476.26741 | R15: =$A$41*M15*9.8*O15*(N15/O15)^$A$43 -> 432.87646 | S15: =SQRT(4*R15/N15^2/M15+9.8/(N15))/2/PI() -> 0.57222572
D16: 平面转动 | E16: 0.7112 | F16: 0.68361 | G16: =(F16-E16)/E16 -> -0.038793588 | H16: =SQRT(H15^2*556/(256.85+1.62*50.1)*0.9^2) -> 0.65443661 | I16: =(H16-E16)/E16 -> -0.079813544 | K16: =SQRT(K15^2*556/(256.85+1.62*50.1)*0.9^2) -> 0.5753926 | L16: =(K16-E16)/E16 -> -0.19095529 | M16: 556.6 | N16: 0.999
C17: R | D17: 径向平动 | E17: 0.5633 | F17: 0.56828 | G17: =(F17-E17)/E17 -> 0.0088407598 | H17: =[1]test_program!$P$21 -> 0.56696172 | I17: =(H17-E17)/E17 -> 0.0065004825 | J17: =N17*1000 -> 999 | K17: =1/2/PI()*SQRT(9.8*1000/J17) -> 0.49848308 | L17: =(K17-E17)/E17 -> -0.11506642 | M17: 556.6 | N17: 0.999 | O17: 0.008 | P17: =((E17*2*PI())^2-9.8/N17)/4*N17^2*M17 -> 377.3098 | R17: =$A$31*M17*9.8*O17*(N17/O17)^$A$33 -> 432.87646 | S17: =SQRT(4*R17/N17^2/M17+9.8/(N17))/2/PI() -> 0.57222572
D18: 轴向平动 | E18: 0.5633 | F18: 0.57217 | G18: =(F18-E18)/E18 -> 0.015746494 | H18: =[1]test_program!$P$21 -> 0.56696172 | I18: =(H18-E18)/E18 -> 0.0065004825 | J18: =N18*1000 -> 999 | K18: =1/2/PI()*SQRT(9.8*1000/J18) -> 0.49848308 | L18: =(K18-E18)/E18 -> -0.11506642 | M18: 556.6 | N18: 0.999 | O18: 0.008 | Q18: =((E18*2*PI())^2-9.8/N18)/4*N18^2*M18 -> 377.3098 | R18: =$A$41*M18*9.8*O18*(N18/O18)^$A$43 -> 432.87646 | S18: =SQRT(4*R18/N18^2/M18+9.8/(N18))/2/PI() -> 0.57222572
D19: 平面转动 | E19: 0.6606 | F19: 0.68361 | G19: =(F19-E19)/E19 -> 0.034831971 | H19: =SQRT(H18^2*556/(256.85+1.62*50.1)*0.9^2) -> 0.65443661 | I19: =(H19-E19)/E19 -> -0.009329992 | K19: =SQRT(K18^2*556/(256.85+1.62*50.1)*0.9^2) -> 0.5753926 | L19: =(K19-E19)/E19 -> -0.12898486 | M19: 556.6 | N19: 0.999
B20: CA_13_Top | C20: A | D20: 径向平动 | E20: 0.4346 | F20: 0.42842 | G20: =(F20-E20)/E20 -> -0.014219972 | H20: =[1]test_program!$P$22 -> 0.42863013 | I20: =(H20-E20)/E20 -> -0.013736472 | J20: =N20*1000 -> 1599 | K20: =1/2/PI()*SQRT(9.8*1000/J20) -> 0.39401154 | L20: =(K20-E20)/E20 -> -0.093392692 | M20: 556.6 | N20: 1.599 | O20: 0.008 | P20: =((E20*2*PI())^2-9.8/N20)/4*N20^2*M20 -> 472.38214 | R20: =$A$31*M20*9.8*O20*(N20/O20)^$A$33 -> 373.47365 | S20: =SQRT(4*R20/N20^2/M20+9.8/(N20))/2/PI() -> 0.42642139
D21: 轴向平动 | E21: 0.4346 | F21: 0.43005 | G21: =(F21-E21)/E21 -> -0.010469397 | H21: =[1]test_program!$P$22 -> 0.42863013 | I21: =(H21-E21)/E21 -> -0.013736472 | J21: =N21*1000 -> 1599 | K21: =1/2/PI()*SQRT(9.8*1000/J21) -> 0.39401154 | L21: =(K21-E21)/E21 -> -0.093392692 | M21: 556.6 | N21: 1.599 | O21: 0.008 | Q21: =((E21*2*PI())^2-9.8/N21)/4*N21^2*M21 -> 472.38214 | R21: =$A$41*M21*9.8*O21*(N21/O21)^$A$43 -> 373.47365 | S21: =SQRT(4*R21/N21^2/M21+9.8/(N21))/2/PI() -> 0.42642139
D22: 平面转动 | E22: 0.5654 | F22: 0.57863 | G22: =(F22-E22)/E22 -> 0.023399363 | H22: =SQRT(H21^2*556/(256.85+1.62*50.1)*0.9^2) -> 0.49476223 | I22: =(H22-E22)/E22 -> -0.12493415 | K22: =SQRT(K21^2*556/(256.85+1.62*50.1)*0.9^2) -> 0.45480244 | L22: =(K22-E22)/E22 -> -0.19560941 | M22: 556.6 | N22: 1.599
C23: R | D23: 径向平动 | E23: 0.4371 | F23: 0.42842 | G23: =(F23-E23)/E23 -> -0.019858156 | H23: =[1]test_program!$P$22 -> 0.42863013 | I23: =(H23-E23)/E23 -> -0.019377421 | J23: =N23*1000 -> 1599 | K23: =1/2/PI()*SQRT(9.8*1000/J23) -> 0.39401154 | L23: =(K23-E23)/E23 -> -0.098578046 | M23: 556.6 | N23: 1.599 | O23: 0.008 | P23: =((E23*2*PI())^2-9.8/N23)/4*N23^2*M23 -> 502.99098 | R23: =$A$31*M23*9.8*O23*(N23/O23)^$A$33 -> 373.47365 | S23: =SQRT(4*R23/N23^2/M23+9.8/(N23))/2/PI() -> 0.42642139
D24: 轴向平动 | E24: 0.4371 | F24: 0.43005 | G24: =(F24-E24)/E24 -> -0.016129032 | H24: =[1]test_program!$P$22 -> 0.42863013 | I24: =(H24-E24)/E24 -> -0.019377421 | J24: =N24*1000 -> 1599 | K24: =1/2/PI()*SQRT(9.8*1000/J24) -> 0.39401154 | L24: =(K24-E24)/E24 -> -0.098578046 | M24: 556.6 | N24: 1.599 | O24: 0.008 | Q24: =((E24*2*PI())^2-9.8/N24)/4*N24^2*M24 -> 502.99098 | R24: =$A$41*M24*9.8*O24*(N24/O24)^$A$43 -> 373.47365 | S24: =SQRT(4*R24/N24^2/M24+9.8/(N24))/2/PI() -> 0.42642139
D25: 平面转动 | E25: 0.5612 | F25: 0.57863 | G25: =(F25-E25)/E25 -> 0.031058446 | H25: =SQRT(H24^2*556/(256.85+1.62*50.1)*0.9^2) -> 0.49476223 | I25: =(H25-E25)/E25 -> -0.11838519 | K25: =SQRT(K24^2*556/(256.85+1.62*50.1)*0.9^2) -> 0.45480244 | L25: =(K25-E25)/E25 -> -0.18958938 | M25: 556.6 | N25: 1.599
B26: CA_07+13_Mid | C26: AA | D26: 径向平动 | E26: 0.3421 | F26: 0.3339 | G26: =(F26-E26)/E26 -> -0.0239696 | H26: =[1]test_program!$P$23 -> 0.34568139 | I26: =(H26-E26)/E26 -> 0.010468839 | J26: =N26*1000 -> 2338 | K26: =1/2/PI()*SQRT(9.8*1000/J26) -> 0.32584489 | L26: =(K26-E26)/E26 -> -0.047515665 | M26: 556.6 | N26: 2.338 | O26: 0.008 | P26: =((E26*2*PI())^2-9.8/N26)/4*N26^2*M26 -> 326.03369 | R26: =$A$31*M26*9.8*O26*(N26/O26)^$A$33 -> 331.50052 | S26: =SQRT(4*R26/N26^2/M26+9.8/(N26))/2/PI() -> 0.34236598
D27: 轴向平动 | E27: 0.3421 | F27: 0.33438 | G27: =(F27-E27)/E27 -> -0.022566501 | H27: =[1]test_program!$P$23 -> 0.34568139 | I27: =(H27-E27)/E27 -> 0.010468839 | J27: =N27*1000 -> 2338 | K27: =1/2/PI()*SQRT(9.8*1000/J27) -> 0.32584489 | L27: =(K27-E27)/E27 -> -0.047515665 | M27: 556.6 | N27: 2.338 | O27: 0.008 | Q27: =((E27*2*PI())^2-9.8/N27)/4*N27^2*M27 -> 326.03369 | R27: =$A$41*M27*9.8*O27*(N27/O27)^$A$43 -> 331.50052 | S27: =SQRT(4*R27/N27^2/M27+9.8/(N27))/2/PI() -> 0.34236598
D28: 平面转动 | E28: 0.4118 | F28: 0.40032 | G28: =(F28-E28)/E28 -> -0.02787761 | H28: =SQRT(H27^2*556/(256.85+1.62*50.1)*0.9^2) -> 0.39901557 | I28: =(H28-E28)/E28 -> -0.031045235 | K28: =SQRT(K27^2*556/(256.85+1.62*50.1)*0.9^2) -> 0.37611856 | L28: =(K28-E28)/E28 -> -0.086647505 | M28: 556.6 | N28: 2.338
A29: RADIAL | C29: AR | D29: 径向平动 | E29: 0.3425 | F29: 0.3339 | G29: =(F29-E29)/E29 -> -0.025109489 | H29: =[1]test_program!$P$23 -> 0.34568139 | I29: =(H29-E29)/E29 -> 0.009288729 | J29: =N29*1000 -> 2338 | K29: =1/2/PI()*SQRT(9.8*1000/J29) -> 0.32584489 | L29: =(K29-E29)/E29 -> -0.048628055 | M29: 556.6 | N29: 2.338 | O29: 0.008 | P29: =((E29*2*PI())^2-9.8/N29)/4*N29^2*M29 -> 334.25666 | R29: =$A$31*M29*9.8*O29*(N29/O29)^$A$33 -> 331.50052 | S29: =SQRT(4*R29/N29^2/M29+9.8/(N29))/2/PI() -> 0.34236598
A30: A | D30: 轴向平动 | E30: 0.3425 | F30: 0.33438 | G30: =(F30-E30)/E30 -> -0.023708029 | H30: =[1]test_program!$P$23 -> 0.34568139 | I30: =(H30-E30)/E30 -> 0.009288729 | J30: =N30*1000 -> 2338 | K30: =1/2/PI()*SQRT(9.8*1000/J30) -> 0.32584489 | L30: =(K30-E30)/E30 -> -0.048628055 | M30: 556.6 | N30: 2.338 | O30: 0.008 | Q30: =((E30*2*PI())^2-9.8/N30)/4*N30^2*M30 -> 334.25666 | R30: =$A$41*M30*9.8*O30*(N30/O30)^$A$43 -> 331.50052 | S30: =SQRT(4*R30/N30^2/M30+9.8/(N30))/2/PI() -> 0.34236598
A31: 45.121 | D31: 平面转动 | E31: 0.4035 | F31: 0.40032 | G31: =(F31-E31)/E31 -> -0.0078810409 | H31: =SQRT(H30^2*556/(256.85+1.62*50.1)*0.9^2) -> 0.39901557 | I31: =(H31-E31)/E31 -> -0.011113823 | K31: =SQRT(K30^2*556/(256.85+1.62*50.1)*0.9^2) -> 0.37611856 | L31: =(K31-E31)/E31 -> -0.067859832 | M31: 556.6 | N31: 2.338
A32: B | C32: RA | D32: 径向平动 | E32: 0.3378 | F32: 0.3339 | G32: =(F32-E32)/E32 -> -0.011545293 | H32: =[1]test_program!$P$23 -> 0.34568139 | I32: =(H32-E32)/E32 -> 0.023331527 | J32: =N32*1000 -> 2338 | K32: =1/2/PI()*SQRT(9.8*1000/J32) -> 0.32584489 | L32: =(K32-E32)/E32 -> -0.035391086 | M32: 556.6 | N32: 2.338 | O32: 0.008 | P32: =((E32*2*PI())^2-9.8/N32)/4*N32^2*M32 -> 238.24361 | R32: =$A$31*M32*9.8*O32*(N32/O32)^$A$33 -> 331.50052 | S32: =SQRT(4*R32/N32^2/M32+9.8/(N32))/2/PI() -> 0.34236598
A33: -0.3138 | D33: 轴向平动 | E33: 0.3378 | F33: 0.33438 | G33: =(F33-E33)/E33 -> -0.010124334 | H33: =[1]test_program!$P$23 -> 0.34568139 | I33: =(H33-E33)/E33 -> 0.023331527 | J33: =N33*1000 -> 2338 | K33: =1/2/PI()*SQRT(9.8*1000/J33) -> 0.32584489 | L33: =(K33-E33)/E33 -> -0.035391086 | M33: 556.6 | N33: 2.338 | O33: 0.008 | Q33: =((E33*2*PI())^2-9.8/N33)/4*N33^2*M33 -> 238.24361 | R33: =$A$41*M33*9.8*O33*(N33/O33)^$A$43 -> 331.50052 | S33: =SQRT(4*R33/N33^2/M33+9.8/(N33))/2/PI() -> 0.34236598
D34: 平面转动 | E34: 0.4039 | F34: 0.40032 | G34: =(F34-E34)/E34 -> -0.0088635801 | H34: =SQRT(H33^2*556/(256.85+1.62*50.1)*0.9^2) -> 0.39901557 | I34: =(H34-E34)/E34 -> -0.012093161 | K34: =SQRT(K33^2*556/(256.85+1.62*50.1)*0.9^2) -> 0.37611856 | L34: =(K34-E34)/E34 -> -0.068782972 | M34: 556.6 | N34: 2.338
C35: RR | D35: 径向平动 | E35: 0.3412 | F35: 0.3339 | G35: =(F35-E35)/E35 -> -0.021395076 | H35: =[1]test_program!$P$23 -> 0.34568139 | I35: =(H35-E35)/E35 -> 0.013134202 | J35: =N35*1000 -> 2338 | K35: =1/2/PI()*SQRT(9.8*1000/J35) -> 0.32584489 | L35: =(K35-E35)/E35 -> -0.04500325 | M35: 556.6 | N35: 2.338 | O35: 0.008 | P35: =((E35*2*PI())^2-9.8/N35)/4*N35^2*M35 -> 307.56713 | R35: =$A$31*M35*9.8*O35*(N35/O35)^$A$33 -> 331.50052 | S35: =SQRT(4*R35/N35^2/M35+9.8/(N35))/2/PI() -> 0.34236598
D36: 轴向平动 | E36: 0.3412 | F36: 0.33438 | G36: =(F36-E36)/E36 -> -0.019988277 | H36: =[1]test_program!$P$23 -> 0.34568139 | I36: =(H36-E36)/E36 -> 0.013134202 | J36: =N36*1000 -> 2338 | K36: =1/2/PI()*SQRT(9.8*1000/J36) -> 0.32584489 | L36: =(K36-E36)/E36 -> -0.04500325 | M36: 556.6 | N36: 2.338 | O36: 0.008 | Q36: =((E36*2*PI())^2-9.8/N36)/4*N36^2*M36 -> 307.56713 | R36: =$A$41*M36*9.8*O36*(N36/O36)^$A$43 -> 331.50052 | S36: =SQRT(4*R36/N36^2/M36+9.8/(N36))/2/PI() -> 0.34236598
D37: 平面转动 | E37: 0.3994 | F37: 0.40032 | G37: =(F37-E37)/E37 -> 0.0023034552 | H37: =SQRT(H36^2*556/(256.85+1.62*50.1)*0.9^2) -> 0.39901557 | I37: =(H37-E37)/E37 -> -0.00096251311 | K37: =SQRT(K36^2*556/(256.85+1.62*50.1)*0.9^2) -> 0.37611856 | L37: =(K37-E37)/E37 -> -0.058291043 | M37: 556.6 | N37: 2.338
B38: CA_13+07_Mid | C38: AA | D38: 径向平动 | E38: 0.3394 | F38: 0.33452 | G38: =(F38-E38)/E38 -> -0.014378315 | H38: =[1]test_program!$P$24 -> 0.34568139 | I38: =(H38-E38)/E38 -> 0.018507336 | J38: =N38*1000 -> 2338 | K38: =1/2/PI()*SQRT(9.8*1000/J38) -> 0.32584489 | L38: =(K38-E38)/E38 -> -0.039938447 | M38: 556.6 | N38: 2.338 | O38: 0.008 | P38: =((E38*2*PI())^2-9.8/N38)/4*N38^2*M38 -> 270.77996 | R38: =$A$31*M38*9.8*O38*(N38/O38)^$A$33 -> 331.50052 | S38: =SQRT(4*R38/N38^2/M38+9.8/(N38))/2/PI() -> 0.34236598
A39: AXIAL | D39: 轴向平动 | E39: 0.3394 | F39: 0.33484 | G39: =(F39-E39)/E39 -> -0.013435474 | H39: =[1]test_program!$P$24 -> 0.34568139 | I39: =(H39-E39)/E39 -> 0.018507336 | J39: =N39*1000 -> 2338 | K39: =1/2/PI()*SQRT(9.8*1000/J39) -> 0.32584489 | L39: =(K39-E39)/E39 -> -0.039938447 | M39: 556.6 | N39: 2.338 | O39: 0.008 | Q39: =((E39*2*PI())^2-9.8/N39)/4*N39^2*M39 -> 270.77996 | R39: =$A$41*M39*9.8*O39*(N39/O39)^$A$43 -> 331.50052 | S39: =SQRT(4*R39/N39^2/M39+9.8/(N39))/2/PI() -> 0.34236598
A40: A | D40: 平面转动 | E40: 0.4109 | F40: 0.40132 | G40: =(F40-E40)/E40 -> -0.023314675 | H40: =SQRT(H39^2*556/(256.85+1.62*50.1)*0.9^2) -> 0.39901557 | I40: =(H40-E40)/E40 -> -0.02892292 | K40: =SQRT(K39^2*556/(256.85+1.62*50.1)*0.9^2) -> 0.37611856 | L40: =(K40-E40)/E40 -> -0.084646976 | M40: 556.6 | N40: 2.338
...

Sheet TB
A1: 管道吊架分组 | B1: 组件 | C1: 组件方向 | D1: 模态方向 | E1: 试验结果 | F1: 模拟结果 | G1: 差距百分比 | H1: 计算结果 | I1: 差距百分比 | J1: 摆长 | K1: 单摆结果 | L1: 差距百分比 | M1: m(kg) | N1: l(m) | O1: r | P1: k_θ_radial_cor | Q1: k_θ_axial_cor | S1: 回归结果
A2: 三孔管夹/TB | B2: TB_07 | C2: A | D2: 径向平动 | E2: 0.4682 | F2: 0.4772 | G2: =(F2-E2)/E2 -> 0.019222554 | H2: =[1]test_program!$Q$5 -> 0.49808603 | I2: =(H2-E2)/E2 -> 0.06383175 | J2: =N2*1000 -> 1168 | K2: =1/2/PI()*SQRT(9.8*1000/J2) -> 0.46101149 | L2: =(K2-E2)/E2 -> -0.015353506 | M2: 417.74 | N2: 1.168 | O2: 0.008 | P2: =((E2*2*PI())^2-9.8/N2)/2*N2^2*M2 -> 75.140666 | R2: =$A$31*M2*9.8*O2*(N2/O2)^$A$33 -> 35.280848 | S2: =SQRT(2*R2/N2^2/M2+9.8/(N2))/2/PI() -> 0.46440057
A3: m(kg)_radial | D3: 轴向平动 | E3: 0.6099 | F3: 0.64608 | G3: =(F3-E3)/E3 -> 0.0593212 | H3: =[1]test_program!$P$5 -> 0.69235565 | I3: =(H3-E3)/E3 -> 0.13519536 | J3: =N3*1000 -> 778 | K3: =1/2/PI()*SQRT(9.8*1000/J3) -> 0.56486332 | L3: =(K3-E3)/E3 -> -0.073842735 | M3: 417.74 | N3: 0.778 | O3: 0.008 | Q3: =((E3*2*PI())^2-9.8/N3)/4*N3^2*M3 -> 132.03279 | R3: =$A$41*M3*9.8*O3*(N3/O3)^$A$43 -> 92.531023 | S3: =SQRT(4*R3/N3^2/M3+9.8/(N3))/2/PI() -> 0.59678227
A4: -61.3741 | D4: 平面转动 | E4: 0.6965 | F4: 0.73603 | G4: =(F4-E4)/E4 -> 0.056755205 | H4: =[1]test_program!$W$5 -> 0.79505368 | I4: =(H4-E4)/E4 -> 0.14149847 | K4: =SQRT(K3^2*388/256.85*0.85^2) -> 0.59011734 | L4: =(K4-E4)/E4 -> -0.15273893 | M4: 417.74
A5: l(m)_radial | C5: R | D5: 径向平动 | E5: 0.4677 | F5: 0.4772 | G5: =(F5-E5)/E5 -> 0.020312166 | H5: =[1]test_program!$Q$5 -> 0.49808603 | I5: =(H5-E5)/E5 -> 0.064969052 | J5: =N5*1000 -> 1168 | K5: =1/2/PI()*SQRT(9.8*1000/J5) -> 0.46101149 | L5: =(K5-E5)/E5 -> -0.014300859 | M5: 417.74 | N5: 1.168 | O5: 0.008 | P5: =((E5*2*PI())^2-9.8/N5)/2*N5^2*M5 -> 69.876605 | R5: =$A$31*M5*9.8*O5*(N5/O5)^$A$33 -> 35.280848 | S5: =SQRT(2*R5/N5^2/M5+9.8/(N5))/2/PI() -> 0.46440057
A6: 981.6565 | D6: 轴向平动 | E6: 0.6095 | F6: 0.64608 | G6: =(F6-E6)/E6 -> 0.060016407 | H6: =[1]test_program!$P$5 -> 0.69235565 | I6: =(H6-E6)/E6 -> 0.13594036 | J6: =N6*1000 -> 778 | K6: =1/2/PI()*SQRT(9.8*1000/J6) -> 0.56486332 | L6: =(K6-E6)/E6 -> -0.073234921 | M6: 417.74 | N6: 0.778 | O6: 0.008 | Q6: =((E6*2*PI())^2-9.8/N6)/4*N6^2*M6 -> 130.81556 | R6: =$A$41*M6*9.8*O6*(N6/O6)^$A$43 -> 92.531023 | S6: =SQRT(4*R6/N6^2/M6+9.8/(N6))/2/PI() -> 0.59678227
A7: c_radial | D7: 平面转动 | E7: 0.6962 | F7: 0.73603 | G7: =(F7-E7)/E7 -> 0.057210572 | H7: =[1]test_program!$W$5 -> 0.79505368 | I7: =(H7-E7)/E7 -> 0.14199035 | K7: =SQRT(K6^2*388/256.85*0.85^2) -> 0.59011734 | L7: =(K7-E7)/E7 -> -0.15237383 | M7: 417.74
A8: 12432.353 | B8: TB_13 | C8: A | D8: 径向平动 | E8: 0.3691 | F8: 0.38437 | G8: =(F8-E8)/E8 -> 0.041370902 | H8: =[1]test_program!$Q$6 -> 0.39487256 | I8: =(H8-E8)/E8 -> 0.069825421 | J8: =N8*1000 -> 1768 | K8: =1/2/PI()*SQRT(9.8*1000/J8) -> 0.3747072 | L8: =(K8-E8)/E8 -> 0.015191549 | M8: 417.74 | N8: 1.768 | O8: 0.008 | P8: =((E8*2*PI())^2-9.8/N8)/2*N8^2*M8 -> -107.49959 | R8: =$A$31*M8*9.8*O8*(N8/O8)^$A$33 -> 62.451564 | S8: =SQRT(2*R8/N8^2/M8+9.8/(N8))/2/PI() -> 0.37792649
A9: ml | D9: 轴向平动 | E9: 0.4457 | F9: 0.46258 | G9: =(F9-E9)/E9 -> 0.037873009 | H9: =[1]test_program!$P$6 -> 0.48086924 | I9: =(H9-E9)/E9 -> 0.078907868 | J9: =N9*1000 -> 1378 | K9: =1/2/PI()*SQRT(9.8*1000/J9) -> 0.42443243 | L9: =(K9-E9)/E9 -> -0.04771723 | M9: 417.74 | N9: 1.378 | O9: 0.008 | Q9: =((E9*2*PI())^2-9.8/N9)/4*N9^2*M9 -> 144.87967 | R9: =$A$41*M9*9.8*O9*(N9/O9)^$A$43 -> 145.28533 | S9: =SQRT(4*R9/N9^2/M9+9.8/(N9))/2/PI() -> 0.44575812
A10: -3.1396 | D10: 平面转动 | E10: 0.4848 | F10: 0.53498 | G10: =(F10-E10)/E10 -> 0.1035066 | H10: =[1]test_program!$W$6 -> 0.55219721 | I10: =(H10-E10)/E10 -> 0.13902065 | K10: =SQRT(K9^2*388/256.85*0.85^2) -> 0.44340804 | L10: =(K10-E10)/E10 -> -0.085379454 | M10: 417.74
A11: m2 | C11: R | D11: 径向平动 | E11: 0.3704 | F11: 0.38437 | G11: =(F11-E11)/E11 -> 0.037715983 | H11: =[1]test_program!$Q$6 -> 0.39487256 | I11: =(H11-E11)/E11 -> 0.066070635 | J11: =N11*1000 -> 1768 | K11: =1/2/PI()*SQRT(9.8*1000/J11) -> 0.3747072 | L11: =(K11-E11)/E11 -> 0.011628512 | M11: 417.74 | N11: 1.768 | O11: 0.008 | P11: =((E11*2*PI())^2-9.8/N11)/2*N11^2*M11 -> -82.720702 | R11: =$A$31*M11*9.8*O11*(N11/O11)^$A$33 -> 62.451564 | S11: =SQRT(2*R11/N11^2/M11+9.8/(N11))/2/PI() -> 0.37792649
A12: 0.0775 | D12: 轴向平动 | E12: 0.4496 | F12: 0.46258 | G12: =(F12-E12)/E12 -> 0.028870107 | H12: =[1]test_program!$P$6 -> 0.48086924 | I12: =(H12-E12)/E12 -> 0.069549014 | J12: =N12*1000 -> 1378 | K12: =1/2/PI()*SQRT(9.8*1000/J12) -> 0.42443243 | L12: =(K12-E12)/E12 -> -0.05597769 | M12: 417.74 | N12: 1.378 | O12: 0.008 | Q12: =((E12*2*PI())^2-9.8/N12)/4*N12^2*M12 -> 172.21583 | R12: =$A$41*M12*9.8*O12*(N12/O12)^$A$43 -> 145.28533 | S12: =SQRT(4*R12/N12^2/M12+9.8/(N12))/2/PI() -> 0.44575812
A13: l2 | D13: 平面转动 | E13: 0.485 | F13: 0.53498 | G13: =(F13-E13)/E13 -> 0.10305155 | H13: =[1]test_program!$W$6 -> 0.55219721 | I13: =(H13-E13)/E13 -> 0.13855095 | K13: =SQRT(K12^2*388/256.85*0.85^2) -> 0.44340804 | L13: =(K13-E13)/E13 -> -0.085756617 | M13: 417.74
A14: 100.4752 | B14: TB_07_Top | C14: A | D14: 径向平动 | E14: 0.4256 | F14: 0.43662 | G14: =(F14-E14)/E14 -> 0.025892857 | H14: =[1]test_program!$Q$7 -> 0.44251976 | I14: =(H14-E14)/E14 -> 0.039755067 | J14: =N14*1000 -> 1428 | K14: =1/2/PI()*SQRT(9.8*1000/J14) -> 0.41693568 | L14: =(K14-E14)/E14 -> -0.020357887 | M14: 451.94 | N14: 1.428 | O14: 0.008 | P14: =((E14*2*PI())^2-9.8/N14)/2*N14^2*M14 -> 132.79739 | R14: =$A$31*M14*9.8*O14*(N14/O14)^$A$33 -> 50.344187 | S14: =SQRT(2*R14/N14^2/M14+9.8/(N14))/2/PI() -> 0.4202414
D15: 轴向平动 | E15: 0.5628 | F15: 0.5588 | G15: =(F15-E15)/E15 -> -0.0071073205 | H15: =[1]test_program!$P$7 -> 0.56778531 | I15: =(H15-E15)/E15 -> 0.0088580536 | J15: =N15*1000 -> 1038 | K15: =1/2/PI()*SQRT(9.8*1000/J15) -> 0.48902886 | L15: =(K15-E15)/E15 -> -0.13107878 | M15: 451.94 | N15: 1.038 | O15: 0.008 | Q15: =((E15*2*PI())^2-9.8/N15)/4*N15^2*M15 -> 372.91237 | R15: =$A$41*M15*9.8*O15*(N15/O15)^$A$43 -> 125.68514 | S15: =SQRT(4*R15/N15^2/M15+9.8/(N15))/2/PI() -> 0.51507423
A16: m(kg)_axial | D16: 平面转动 | E16: 0.599 | F16: 0.64011 | G16: =(F16-E16)/E16 -> 0.068631052 | H16: =[1]test_program!$W$7 -> 0.67817024 | I16: =(H16-E16)/E16 -> 0.13217069 | K16: =SQRT(K15^2*422.2/256.85*0.85^2) -> 0.53293317 | L16: =(K16-E16)/E16 -> -0.11029522 | M16: 451.94
A17: -156.5354 | C17: R | D17: 径向平动 | E17: 0.4224 | F17: 0.43662 | G17: =(F17-E17)/E17 -> 0.033664773 | H17: =[1]test_program!$Q$7 -> 0.44251976 | I17: =(H17-E17)/E17 -> 0.047632 | J17: =N17*1000 -> 1428 | K17: =1/2/PI()*SQRT(9.8*1000/J17) -> 0.41693568 | L17: =(K17-E17)/E17 -> -0.012936356 | M17: 451.94 | N17: 1.428 | O17: 0.008 | P17: =((E17*2*PI())^2-9.8/N17)/2*N17^2*M17 -> 83.433119 | R17: =$A$31*M17*9.8*O17*(N17/O17)^$A$33 -> 50.344187 | S17: =SQRT(2*R17/N17^2/M17+9.8/(N17))/2/PI() -> 0.4202414
A18: l(m)_axial | D18: 轴向平动 | E18: 0.5294 | F18: 0.5588 | G18: =(F18-E18)/E18 -> 0.055534567 | H18: =[1]test_program!$P$7 -> 0.56778531 | I18: =(H18-E18)/E18 -> 0.072507202 | J18: =N18*1000 -> 1038 | K18: =1/2/PI()*SQRT(9.8*1000/J18) -> 0.48902886 | L18: =(K18-E18)/E18 -> -0.076258286 | M18: 451.94 | N18: 1.038 | O18: 0.008 | Q18: =((E18*2*PI())^2-9.8/N18)/4*N18^2*M18 -> 197.59544 | R18: =$A$41*M18*9.8*O18*(N18/O18)^$A$43 -> 125.68514 | S18: =SQRT(4*R18/N18^2/M18+9.8/(N18))/2/PI() -> 0.51507423
A19: 4200.5457 | D19: 平面转动 | E19: 0.5712 | F19: 0.64011 | G19: =(F19-E19)/E19 -> 0.12064076 | H19: =[1]test_program!$W$7 -> 0.67817024 | I19: =(H19-E19)/E19 -> 0.18727283 | K19: =SQRT(K18^2*422.2/256.85*0.85^2) -> 0.53293317 | L19: =(K19-E19)/E19 -> -0.066993758 | M19: 451.94
A20: c_axial | B20: TB_13_Top | C20: A | D20: 径向平动 | E20: 0.3517 | F20: 0.36202 | G20: =(F20-E20)/E20 -> 0.02934319 | H20: =[1]test_program!$Q$8 -> 0.36511227 | I20: =(H20-E20)/E20 -> 0.038135537 | J20: =N20*1000 -> 2028 | K20: =1/2/PI()*SQRT(9.8*1000/J20) -> 0.34986395 | L20: =(K20-E20)/E20 -> -0.0052205025 | M20: 451.94 | N20: 2.028 | O20: 0.008 | P20: =((E20*2*PI())^2-9.8/N20)/2*N20^2*M20 -> 47.260506 | R20: =$A$31*M20*9.8*O20*(N20/O20)^$A$33 -> 81.620138 | S20: =SQRT(2*R20/N20^2/M20+9.8/(N20))/2/PI() -> 0.35302886
A21: 30658.237 | D21: 轴向平动 | E21: 0.4026 | F21: 0.42513 | G21: =(F21-E21)/E21 -> 0.055961252 | H21: =[1]test_program!$P$8 -> 0.43008401 | I21: =(H21-E21)/E21 -> 0.068266304 | J21: =N21*1000 -> 1638 | K21: =1/2/PI()*SQRT(9.8*1000/J21) -> 0.38929266 | L21: =(K21-E21)/E21 -> -0.03305349 | M21: 451.94 | N21: 1.638 | O21: 0.008 | Q21: =((E21*2*PI())^2-9.8/N21)/4*N21^2*M21 -> 126.11471 | R21: =$A$41*M21*9.8*O21*(N21/O21)^$A$43 -> 180.15135 | S21: =SQRT(4*R21/N21^2/M21+9.8/(N21))/2/PI() -> 0.40816907
A22: ml | D22: 平面转动 | E22: 0.4517 | F22: 0.49598 | G22: =(F22-E22)/E22 -> 0.098029666 | H22: =[1]test_program!$W$8 -> 0.513698 | I22: =(H22-E22)/E22 -> 0.13725481 | K22: =SQRT(K21^2*422.2/256.85*0.85^2) -> 0.4242428 | L22: =(K22-E22)/E22 -> -0.060786372 | M22: 451.94
A23: -11.1247 | C23: R | D23: 径向平动 | E23: 0.352 | F23: 0.36202 | G23: =(F23-E23)/E23 -> 0.028465909 | H23: =[1]test_program!$Q$8 -> 0.36511227 | I23: =(H23-E23)/E23 -> 0.037250762 | J23: =N23*1000 -> 2028 | K23: =1/2/PI()*SQRT(9.8*1000/J23) -> 0.34986395 | L23: =(K23-E23)/E23 -> -0.0060683259 | M23: 451.94 | N23: 2.028 | O23: 0.008 | P23: =((E23*2*PI())^2-9.8/N23)/2*N23^2*M23 -> 55.006109 | R23: =$A$31*M23*9.8*O23*(N23/O23)^$A$33 -> 81.620138 | S23: =SQRT(2*R23/N23^2/M23+9.8/(N23))/2/PI() -> 0.35302886
A24: m2 | D24: 轴向平动 | E24: 0.4072 | F24: 0.42513 | G24: =(F24-E24)/E24 -> 0.044032417 | H24: =[1]test_program!$P$8 -> 0.43008401 | I24: =(H24-E24)/E24 -> 0.056198463 | J24: =N24*1000 -> 1638 | K24: =1/2/PI()*SQRT(9.8*1000/J24) -> 0.38929266 | L24: =(K24-E24)/E24 -> -0.043976756 | M24: 451.94 | N24: 1.638 | O24: 0.008 | Q24: =((E24*2*PI())^2-9.8/N24)/4*N24^2*M24 -> 170.6951 | R24: =$A$41*M24*9.8*O24*(N24/O24)^$A$43 -> 180.15135 | S24: =SQRT(4*R24/N24^2/M24+9.8/(N24))/2/PI() -> 0.40816907
A25: 0.202 | D25: 平面转动 | E25: 0.454 | F25: 0.49598 | G25: =(F25-E25)/E25 -> 0.09246696 | H25: =[1]test_program!$W$8 -> 0.513698 | I25: =(H25-E25)/E25 -> 0.13149339 | K25: =SQRT(K24^2*422.2/256.85*0.85^2) -> 0.4242428 | L25: =(K25-E25)/E25 -> -0.065544503 | M25: 451.94
A26: l2 | B26: TB_07+07_Mid | C26: AA | D26: 径向平动 | E26: 0.334 | F26: 0.34011 | G26: =(F26-E26)/E26 -> 0.018293413 | H26: =[1]test_program!$Q$9 -> 0.34714233 | I26: =(H26-E26)/E26 -> 0.039348289 | J26: =N26*1000 -> 2227 | K26: =1/2/PI()*SQRT(9.8*1000/J26) -> 0.33386667 | L26: =(K26-E26)/E26 -> -0.000399202 | M26: 451.94 | N26: 2.227 | O26: 0.008 | P26: =((E26*2*PI())^2-9.8/N26)/2*N26^2*M26 -> 3.9398519 | R26: =$A$31*M26*9.8*O26*(N26/O26)^$A$33 -> 92.852975 | S26: =SQRT(2*R26/N26^2/M26+9.8/(N26))/2/PI() -> 0.33699499
A27: 198.2246 | D27: 轴向平动 | E27: 0.3815 | F27: 0.39164 | G27: =(F27-E27)/E27 -> 0.026579292 | H27: =[1]test_program!$P$9 -> 0.40212677 | I27: =(H27-E27)/E27 -> 0.054067553 | J27: =N27*1000 -> 1837 | K27: =1/2/PI()*SQRT(9.8*1000/J27) -> 0.36760261 | L27: =(K27-E27)/E27 -> -0.036428272 | M27: 451.94 | N27: 1.837 | O27: 0.008 | Q27: =((E27*2*PI())^2-9.8/N27)/4*N27^2*M27 -> 156.70154 | R27: =$A$41*M27*9.8*O27*(N27/O27)^$A$43 -> 197.21318 | S27: =SQRT(4*R27/N27^2/M27+9.8/(N27))/2/PI() -> 0.38501126
D28: 平面转动 | E28: 0.43 | F28: 0.45354 | G28: =(F28-E28)/E28 -> 0.054744186 | H28: =[1]test_program!$W$9 -> 0.4803055 | I28: =(H28-E28)/E28 -> 0.11698954 | K28: =SQRT(K27^2*422.2/256.85*0.85^2) -> 0.40060544 | L28: =(K28-E28)/E28 -> -0.068359433 | M28: 451.94
A29: RADIAL | C29: AR | D29: 径向平动 | E29: 0.3334 | F29: 0.34011 | G29: =(F29-E29)/E29 -> 0.020125975 | H29: =[1]test_program!$Q$9 -> 0.34714233 | I29: =(H29-E29)/E29 -> 0.041218742 | J29: =N29*1000 -> 2227 | K29: =1/2/PI()*SQRT(9.8*1000/J29) -> 0.33386667 | L29: =(K29-E29)/E29 -> 0.0013997197 | M29: 451.94 | N29: 2.227 | O29: 0.008 | P29: =((E29*2*PI())^2-9.8/N29)/2*N29^2*M29 -> -13.777076 | R29: =$A$31*M29*9.8*O29*(N29/O29)^$A$33 -> 92.852975 | S29: =SQRT(2*R29/N29^2/M29+9.8/(N29))/2/PI() -> 0.33699499
A30: A | D30: 轴向平动 | E30: 0.3833 | F30: 0.39164 | G30: =(F30-E30)/E30 -> 0.021758414 | H30: =[1]test_program!$P$9 -> 0.40212677 | I30: =(H30-E30)/E30 -> 0.049117588 | J30: =N30*1000 -> 1837 | K30: =1/2/PI()*SQRT(9.8*1000/J30) -> 0.36760261 | L30: =(K30-E30)/E30 -> -0.040953263 | M30: 451.94 | N30: 1.837 | O30: 0.008 | Q30: =((E30*2*PI())^2-9.8/N30)/4*N30^2*M30 -> 177.42295 | R30: =$A$41*M30*9.8*O30*(N30/O30)^$A$43 -> 197.21318 | S30: =SQRT(4*R30/N30^2/M30+9.8/(N30))/2/PI() -> 0.38501126
A31: 0.0011244 | D31: 平面转动 | E31: 0.4297 | F31: 0.45354 | G31: =(F31-E31)/E31 -> 0.055480568 | H31: =[1]test_program!$W$9 -> 0.4803055 | I31: =(H31-E31)/E31 -> 0.11776938 | K31: =SQRT(K30^2*422.2/256.85*0.85^2) -> 0.40060544 | L31: =(K31-E31)/E31 -> -0.067708998 | M31: 451.94
A32: B | C32: RA | D32: 径向平动 | E32: 0.337 | F32: 0.34011 | G32: =(F32-E32)/E32 -> 0.0092284866 | H32: =[1]test_program!$Q$9 -> 0.34714233 | I32: =(H32-E32)/E32 -> 0.03009593 | J32: =N32*1000 -> 2227 | K32: =1/2/PI()*SQRT(9.8*1000/J32) -> 0.33386667 | L32: =(K32-E32)/E32 -> -0.0092977254 | M32: 451.94 | N32: 2.227 | O32: 0.008 | P32: =((E32*2*PI())^2-9.8/N32)/2*N32^2*M32 -> 93.002321 | R32: =$A$31*M32*9.8*O32*(N32/O32)^$A$33 -> 92.852975 | S32: =SQRT(2*R32/N32^2/M32+9.8/(N32))/2/PI() -> 0.33699499
A33: 1.3775 | D33: 轴向平动 | E33: 0.3872 | F33: 0.39164 | G33: =(F33-E33)/E33 -> 0.011466942 | H33: =[1]test_program!$P$9 -> 0.40212677 | I33: =(H33-E33)/E33 -> 0.038550546 | J33: =N33*1000 -> 1837 | K33: =1/2/PI()*SQRT(9.8*1000/J33) -> 0.36760261 | L33: =(K33-E33)/E33 -> -0.050613083 | M33: 451.94 | N33: 1.837 | O33: 0.008 | Q33: =((E33*2*PI())^2-9.8/N33)/4*N33^2*M33 -> 222.65393 | R33: =$A$41*M33*9.8*O33*(N33/O33)^$A$43 -> 197.21318 | S33: =SQRT(4*R33/N33^2/M33+9.8/(N33))/2/PI() -> 0.38501126
D34: 平面转动 | E34: 0.432 | F34: 0.45354 | G34: =(F34-E34)/E34 -> 0.049861111 | H34: =[1]test_program!$W$9 -> 0.4803055 | I34: =(H34-E34)/E34 -> 0.11181829 | K34: =SQRT(K33^2*422.2/256.85*0.85^2) -> 0.40060544 | L34: =(K34-E34)/E34 -> -0.072672584 | M34: 451.94
C35: RR | D35: 径向平动 | E35: 0.3361 | F35: 0.34011 | G35: =(F35-E35)/E35 -> 0.011930973 | H35: =[1]test_program!$Q$9 -> 0.34714233 | I35: =(H35-E35)/E35 -> 0.032854295 | J35: =N35*1000 -> 2227 | K35: =1/2/PI()*SQRT(9.8*1000/J35) -> 0.33386667 | L35: =(K35-E35)/E35 -> -0.0066448482 | M35: 451.94 | N35: 2.227 | O35: 0.008 | P35: =((E35*2*PI())^2-9.8/N35)/2*N35^2*M35 -> 66.19996 | R35: =$A$31*M35*9.8*O35*(N35/O35)^$A$33 -> 92.852975 | S35: =SQRT(2*R35/N35^2/M35+9.8/(N35))/2/PI() -> 0.33699499
D36: 轴向平动 | E36: 0.3868 | F36: 0.39164 | G36: =(F36-E36)/E36 -> 0.012512927 | H36: =[1]test_program!$P$9 -> 0.40212677 | I36: =(H36-E36)/E36 -> 0.039624539 | J36: =N36*1000 -> 1837 | K36: =1/2/PI()*SQRT(9.8*1000/J36) -> 0.36760261 | L36: =(K36-E36)/E36 -> -0.049631297 | M36: 451.94 | N36: 1.837 | O36: 0.008 | Q36: =((E36*2*PI())^2-9.8/N36)/4*N36^2*M36 -> 217.99379 | R36: =$A$41*M36*9.8*O36*(N36/O36)^$A$43 -> 197.21318 | S36: =SQRT(4*R36/N36^2/M36+9.8/(N36))/2/PI() -> 0.38501126
D37: 平面转动 | E37: 0.4266 | F37: 0.45354 | G37: =(F37-E37)/E37 -> 0.063150492 | H37: =[1]test_program!$W$9 -> 0.4803055 | I37: =(H37-E37)/E37 -> 0.12589194 | K37: =SQRT(K36^2*422.2/256.85*0.85^2) -> 0.40060544 | L37: =(K37-E37)/E37 -> -0.060934262 | M37: 451.94
B38: TB_07+13_Mid | C38: AA | D38: 径向平动 | E38: 0.2953 | F38: 0.30095 | G38: =(F38-E38)/E38 -> 0.019133085 | H38: =[1]test_program!$Q$10 -> 0.30564645 | I38: =(H38-E38)/E38 -> 0.035037096 | J38: =N38*1000 -> 2827 | K38: =1/2/PI()*SQRT(9.8*1000/J38) -> 0.29632635 | L38: =(K38-E38)/E38 -> 0.0034756033 | M38: 451.94 | N38: 2.827 | O38: 0.008 | P38: =((E38*2*PI())^2-9.8/N38)/2*N38^2*M38 -> -43.291565 | R38: =$A$31*M38*9.8*O38*(N38/O38)^$A$33 -> 128.97708 | S38: =SQRT(2*R38/N38^2/M38+9.8/(N38))/2/PI() -> 0.29936324
A39: AXIAL | D39: 轴向平动 | E39: 0.3268 | F39: 0.33489 | G39: =(F39-E39)/E39 -> 0.024755202 | H39: =[1]test_program!$P$10 -> 0.34199617 | I39: =(H39-E39)/E39 -> 0.046499894 | J39: =N39*1000 -> 2437 | K39: =1/2/PI()*SQRT(9.8*1000/J39) -> 0.31915776 | L39: =(K39-E39)/E39 -> -0.023385075 | M39: 451.94 | N39: 2.437 | O39: 0.008 | Q39: =((E39*2*PI())^2-9.8/N39)/4*N39^2*M39 -> 130.77253 | R39: =$A$41*M39*9.8*O39*(N39/O39)^$A$43 -> 246.49458 | S39: =SQRT(4*R39/N39^2/M39+9.8/(N39))/2/PI() -> 0.33341665
A40: A | D40: 平面转动 | E40: 0.3621 | F40: 0.39224 | G40: =(F40-E40)/E40 -> 0.083236675 | H40: =[1]test_program!$W$10 -> 0.40848472 | I40: =(H40-E40)/E40 -> 0.12809919 | K40: =SQRT(K39^2*422.2/256.85*0.85^2) -> 0.34781128 | L40: =(K40-E40)/E40 -> -0.039460707 | M40: 451.94
...

Sheet CSBD
A1: 管道吊架分组 | B1: 组件 | C1: 组件方向 | D1: 模态方向 | E1: 试验结果 | F1: 模拟结果 | G1: 差距百分比 | H1: 计算结果 | I1: 差距百分比 | J1: 摆长 | K1: 单摆结果 | L1: 差距百分比 | M1: m(kg) | N1: l(m) | O1: r | P1: k_θ_radial_cor | Q1: k_θ_axial_cor | S1: 回归结果
A2: 拉撑杆/CSBD | B2: CSBD_07 | C2: A | D2: 径向平动 | E2: 0.5457 | F2: 0.50429 | G2: =(F2-E2)/E2 -> -0.075884185 | H2: =[1]test_program!$Q$3 -> 0.52353852 | I2: =(H2-E2)/E2 -> -0.040611111 | J2: 1065 | K2: =1/2/PI()*SQRT(9.8*1000/J2) -> 0.48279011 | L2: =(K2-E2)/E2 -> -0.11528292 | M2: 435.693 | N2: =J2/1000 -> 1.065 | O2: 0.0125 | P2: =((E2*2*PI())^2-9.8/N2)/2*N2^2*M2 -> 631.14418 | R2: =$A$31*M2*9.8*O2*(N2/O2)^$A$33 -> 536.61726 | S2: =SQRT(2*R2/N2^2/M2+9.8/(N2))/2/PI() -> 0.53674761
A3: m(kg)_radial | D3: 轴向平动 | E3: 0.69619 | F3: 0.69941 | G3: =(F3-E3)/E3 -> 0.0046251742 | H3: =[1]test_program!$P$3 -> 0.73787691 | I3: =(H3-E3)/E3 -> 0.059878637 | J3: 700 | K3: =1/2/PI()*SQRT(9.8*1000/J3) -> 0.59550327 | L3: =(K3-E3)/E3 -> -0.14462536 | M3: 435.693 | N3: =J3/1000 -> 0.7 | O3: 0.0125 | Q3: =((E3*2*PI())^2-9.8/N3)/4*N3^2*M3 -> 274.03627 | R3: =$A$31*M3*9.8*O3*(N3/O3)^$A$33 -> 470.13106 | S3: =SQRT(2*R3/N3^2/M3+9.8/(N3))/2/PI() -> 0.68277755
A4: -61.3741 | D4: 平面转动 | E4: 0.8522 | F4: 0.79941 | G4: =(F4-E4)/E4 -> -0.061945553 | H4: =SQRT(H3^2*428/256.85*0.9^2) -> 0.85725204 | I4: =(H4-E4)/E4 -> 0.0059282357 | K4: =SQRT(K3^2*428/256.85*0.9^2) -> 0.69184492 | M4: 435.693
A5: l(m)_radial | C5: R | D5: 径向平动 | E5: 0.5291 | F5: 0.50439 | G5: =(F5-E5)/E5 -> -0.046701947 | H5: =[1]test_program!$Q$3 -> 0.52353852 | I5: =(H5-E5)/E5 -> -0.010511214 | J5: 1065 | K5: =1/2/PI()*SQRT(9.8*1000/J5) -> 0.48279011 | L5: =(K5-E5)/E5 -> -0.087525778 | M5: 435.693 | N5: =J5/1000 -> 1.065 | O5: 0.0125 | P5: =((E5*2*PI())^2-9.8/N5)/2*N5^2*M5 -> 457.1057 | R5: =$A$31*M5*9.8*O5*(N5/O5)^$A$33 -> 536.61726 | S5: =SQRT(2*R5/N5^2/M5+9.8/(N5))/2/PI() -> 0.53674761
A6: 981.6565 | D6: 轴向平动 | E6: 0.7128 | F6: 0.69626 | G6: =(F6-E6)/E6 -> -0.023204265 | H6: =[1]test_program!$P$3 -> 0.73787691 | I6: =(H6-E6)/E6 -> 0.035180848 | J6: 700 | K6: =1/2/PI()*SQRT(9.8*1000/J6) -> 0.59550327 | L6: =(K6-E6)/E6 -> -0.1645577 | M6: 435.693 | N6: =J6/1000 -> 0.7 | O6: 0.0125 | Q6: =((E6*2*PI())^2-9.8/N6)/4*N6^2*M6 -> 323.34842 | R6: =$A$31*M6*9.8*O6*(N6/O6)^$A$33 -> 470.13106 | S6: =SQRT(2*R6/N6^2/M6+9.8/(N6))/2/PI() -> 0.68277755
A7: c_radial | D7: 平面转动 | E7: 0.8596 | F7: 0.79952 | G7: =(F7-E7)/E7 -> -0.069892973 | H7: =SQRT(H6^2*428/256.85*0.9^2) -> 0.85725204 | I7: =(H7-E7)/E7 -> -0.0027314536 | K7: =SQRT(K6^2*428/256.85*0.9^2) -> 0.69184492 | M7: 435.693
A8: 12432.353 | B8: CSBD_13 | C8: A | D8: 径向平动 | E8: 0.4221 | F8: 0.40648 | G8: =(F8-E8)/E8 -> -0.037005449 | H8: =[1]test_program!$Q$4 -> 0.40726484 | I8: =(H8-E8)/E8 -> -0.035146086 | J8: 1665 | K8: =1/2/PI()*SQRT(9.8*1000/J8) -> 0.38612334 | L8: =(K8-E8)/E8 -> -0.085232559 | M8: 435.793 | N8: =J8/1000 -> 1.665 | O8: 0.0125 | P8: =((E8*2*PI())^2-9.8/N8)/2*N8^2*M8 -> 693.41101 | R8: =$A$31*M8*9.8*O8*(N8/O8)^$A$33 -> 617.92174 | S8: =SQRT(2*R8/N8^2/M8+9.8/(N8))/2/PI() -> 0.41833345
A9: ml | D9: 轴向平动 | E9: 0.4763 | F9: 0.4957 | G9: =(F9-E9)/E9 -> 0.040730632 | H9: =[1]test_program!$P$4 -> 0.49596439 | I9: =(H9-E9)/E9 -> 0.041285717 | J9: 1300 | K9: =1/2/PI()*SQRT(9.8*1000/J9) -> 0.43697993 | L9: =(K9-E9)/E9 -> -0.082553154 | M9: 435.793 | N9: =J9/1000 -> 1.3 | O9: 0.0125 | Q9: =((E9*2*PI())^2-9.8/N9)/4*N9^2*M9 -> 261.02666 | R9: =$A$31*M9*9.8*O9*(N9/O9)^$A$33 -> 571.55582 | S9: =SQRT(2*R9/N9^2/M9+9.8/(N9))/2/PI() -> 0.47986122
A10: -3.1396 | D10: 平面转动 | E10: 0.5595 | F10: 0.59438 | G10: =(F10-E10)/E10 -> 0.062341376 | H10: =SQRT(H9^2*428/256.85*0.9^2) -> 0.57620245 | I10: =(H10-E10)/E10 -> 0.02985246 | K10: =SQRT(K9^2*428/256.85*0.9^2) -> 0.50767538 | M10: 435.793
A11: m2 | C11: R | D11: 径向平动 | E11: 0.415 | F11: 0.40648 | G11: =(F11-E11)/E11 -> -0.02053012 | H11: =[1]test_program!$Q$4 -> 0.40726484 | I11: =(H11-E11)/E11 -> -0.018638947 | J11: 1665 | K11: =1/2/PI()*SQRT(9.8*1000/J11) -> 0.38612334 | L11: =(K11-E11)/E11 -> -0.069582321 | M11: 435.793 | N11: =J11/1000 -> 1.665 | O11: 0.0125 | P11: =((E11*2*PI())^2-9.8/N11)/2*N11^2*M11 -> 551.67697 | R11: =$A$31*M11*9.8*O11*(N11/O11)^$A$33 -> 617.92174 | S11: =SQRT(2*R11/N11^2/M11+9.8/(N11))/2/PI() -> 0.41833345
A12: 0.0775 | D12: 轴向平动 | E12: 0.4774 | F12: 0.4957 | G12: =(F12-E12)/E12 -> 0.038332635 | H12: =[1]test_program!$P$4 -> 0.49596439 | I12: =(H12-E12)/E12 -> 0.038886441 | J12: 1300 | K12: =1/2/PI()*SQRT(9.8*1000/J12) -> 0.43697993 | L12: =(K12-E12)/E12 -> -0.084667087 | M12: 435.793 | N12: =J12/1000 -> 1.3 | O12: 0.0125 | Q12: =((E12*2*PI())^2-9.8/N12)/4*N12^2*M12 -> 268.65221 | R12: =$A$31*M12*9.8*O12*(N12/O12)^$A$33 -> 571.55582 | S12: =SQRT(2*R12/N12^2/M12+9.8/(N12))/2/PI() -> 0.47986122
A13: l2 | D13: 平面转动 | E13: 0.5605 | F13: 0.59452 | G13: =(F13-E13)/E13 -> 0.060695807 | H13: =SQRT(H12^2*428/256.85*0.9^2) -> 0.57620245 | I13: =(H13-E13)/E13 -> 0.028015079 | K13: =SQRT(K12^2*428/256.85*0.9^2) -> 0.50767538 | M13: 435.793
A14: 100.4752
A16: m(kg)_axial
A17: -156.5354
A18: l(m)_axial
A19: 4200.5457
A20: c_axial
A21: 30658.237
A22: ml
A23: -11.1247
A24: m2
A25: 0.202
A26: l2
A27: 198.2246
A29: RADIAL
A30: A
A31: 2.4767
A32: B
A33: 0.3152
A39: AXIAL
A40: A
A41: 2.4767
A42: B
A43: 0.3152

Sheet CSB
A1: 管道吊架分组 | B1: 组件 | C1: 组件方向 | D1: 模态方向 | E1: 试验结果 | F1: 模拟结果 | G1: 差距百分比 | H1: 计算结果 | I1: 差距百分比 | J1: 摆长 | K1: 单摆结果 | L1: 差距百分比 | M1: m(kg) | N1: l(m) | O1: r | P1: k_θ_radial_cor | Q1: k_θ_axial_cor | S1: 回归结果
A2: C钢带/CSB | B2: CSB_07 | C2: A | D2: 径向平动 | E2: 0.411 | F2: 0.41856 | G2: =(F2-E2)/E2 -> 0.018394161 | H2: =[1]test_program!$Q$17 -> 0.41447587 | I2: =(H2-E2)/E2 -> 0.0084570937 | J2: 1445 | K2: =1/2/PI()*SQRT(9.8*1000/J2) -> 0.41447586 | L2: =(K2-E2)/E2 -> 0.008457091 | M2: 491 | N2: =J2/1000 -> 1.445 | O2: 0.018 | P2: =((E2*2*PI())^2-9.8/N2)/2*N2^2*M2 -> -58.06496 | R2: =$A$31*M2*9.8*O2*(N2/O2)^$A$33 -> 40.933699 | S2: =SQRT(2*R2/N2^2/M2+9.8/(N2))/2/PI() -> 0.41690881
A3: m(kg)_radial | D3: 轴向平动 | E3: 0.5873 | F3: 0.58435 | G3: =(F3-E3)/E3 -> -0.0050229865 | H3: =[1]test_program!$P$17 -> 0.65747505 | I3: =(H3-E3)/E3 -> 0.11948757 | J3: 810 | K3: =1/2/PI()*SQRT(9.8*1000/J3) -> 0.55359309 | L3: =(K3-E3)/E3 -> -0.057393003 | M3: 491 | N3: =J3/1000 -> 0.81 | O3: 0.018 | Q3: =((E3*2*PI())^2-9.8/N3)/4*N3^2*M3 -> 122.26867 | R3: =$A$41*M3*9.8*O3*(N3/O3)^$A$43 -> 133.20427 | S3: =SQRT(4*R3/N3^2/M3+9.8/(N3))/2/PI() -> 0.59022094
A4: -61.3741 | D4: 平面转动 | E4: 0.81829 | F4: 0.65868 | G4: =(F4-E4)/E4 -> -0.1950531 | H4: =SQRT(H3^2*529/(256.85+1.62*70.5)*0.9^2) -> 0.70652503 | I4: =(H4-E4)/E4 -> -0.13658357 | K4: =SQRT(K3^2*529/(256.85+1.62*70.5)*0.9^2) -> 0.59489311 | L4: =(K4-E4)/E4 -> -0.27300455 | M4: 491
A5: l(m)_radial | C5: R | D5: 径向平动 | E5: 0.4139 | F5: 0.41856 | G5: =(F5-E5)/E5 -> 0.011258758 | H5: =[1]test_program!$Q$17 -> 0.41447587 | I5: =(H5-E5)/E5 -> 0.0013913156 | J5: 1445 | K5: =1/2/PI()*SQRT(9.8*1000/J5) -> 0.41447586 | L5: =(K5-E5)/E5 -> 0.0013913129 | M5: 491 | N5: =J5/1000 -> 1.445 | O5: 0.018 | P5: =((E5*2*PI())^2-9.8/N5)/2*N5^2*M5 -> -9.6537175 | R5: =$A$31*M5*9.8*O5*(N5/O5)^$A$33 -> 40.933699 | S5: =SQRT(2*R5/N5^2/M5+9.8/(N5))/2/PI() -> 0.41690881
A6: 981.6565 | D6: 轴向平动 | E6: 0.5786 | F6: 0.58435 | G6: =(F6-E6)/E6 -> 0.0099377809 | H6: =[1]test_program!$P$17 -> 0.65747505 | I6: =(H6-E6)/E6 -> 0.13632051 | J6: 810 | K6: =1/2/PI()*SQRT(9.8*1000/J6) -> 0.55359309 | L6: =(K6-E6)/E6 -> -0.043219687 | M6: 491 | N6: =J6/1000 -> 0.81 | O6: 0.018 | Q6: =((E6*2*PI())^2-9.8/N6)/4*N6^2*M6 -> 90.01851 | R6: =$A$41*M6*9.8*O6*(N6/O6)^$A$43 -> 133.20427 | S6: =SQRT(4*R6/N6^2/M6+9.8/(N6))/2/PI() -> 0.59022094
A7: c_radial | D7: 平面转动 | E7: 0.82229 | F7: 0.65868 | G7: =(F7-E7)/E7 -> -0.19896873 | H7: =SQRT(H6^2*529/(256.85+1.62*70.5)*0.9^2) -> 0.70652503 | I7: =(H7-E7)/E7 -> -0.14078363 | K7: =SQRT(K6^2*529/(256.85+1.62*70.5)*0.9^2) -> 0.59489311 | L7: =(K7-E7)/E7 -> -0.276541 | M7: 491
A8: 12432.353 | B8: CSB_13 | C8: A | D8: 径向平动 | E8: 0.3485 | F8: 0.35312 | G8: =(F8-E8)/E8 -> 0.013256815 | H8: =[1]test_program!$Q$18 -> 0.34840671 | I8: =(H8-E8)/E8 -> -0.00026767827 | J8: 2045 | K8: =1/2/PI()*SQRT(9.8*1000/J8) -> 0.34840671 | L8: =(K8-E8)/E8 -> -0.0002676837 | M8: 491 | N8: =J8/1000 -> 2.045 | O8: 0.018 | P8: =((E8*2*PI())^2-9.8/N8)/2*N8^2*M8 -> 2.6351007 | R8: =$A$31*M8*9.8*O8*(N8/O8)^$A$33 -> 66.045476 | S8: =SQRT(2*R8/N8^2/M8+9.8/(N8))/2/PI() -> 0.35073737
A9: ml | D9: 轴向平动 | E9: 0.4291 | F9: 0.43784 | G9: =(F9-E9)/E9 -> 0.020368213 | H9: =[1]test_program!$P$18 -> 0.46644714 | I9: =(H9-E9)/E9 -> 0.087035974 | J9: 1410 | K9: =1/2/PI()*SQRT(9.8*1000/J9) -> 0.41958854 | L9: =(K9-E9)/E9 -> -0.022166079 | M9: 491 | N9: =J9/1000 -> 1.41 | O9: 0.018 | Q9: =((E9*2*PI())^2-9.8/N9)/4*N9^2*M9 -> 77.770555 | R9: =$A$41*M9*9.8*O9*(N9/O9)^$A$43 -> 206.30298 | S9: =SQRT(4*R9/N9^2/M9+9.8/(N9))/2/PI() -> 0.44437367
A10: -3.1396 | D10: 平面转动 | E10: 0.69267 | F10: 0.5075 | G10: =(F10-E10)/E10 -> -0.26732788 | H10: =SQRT(H9^2*529/(256.85+1.62*60.5)*0.9^2) -> 0.51255946 | I10: =(H10-E10)/E10 -> -0.26002359 | K10: =SQRT(K9^2*529/(256.85+1.62*60.5)*0.9^2) -> 0.46106848 | L10: =(K10-E10)/E10 -> -0.33436055 | M10: 491
A11: m2 | C11: R | D11: 径向平动 | E11: 0.3504 | F11: 0.35312 | G11: =(F11-E11)/E11 -> 0.0077625571 | H11: =[1]test_program!$Q$18 -> 0.34840671 | I11: =(H11-E11)/E11 -> -0.0056886013 | J11: 2045 | K11: =1/2/PI()*SQRT(9.8*1000/J11) -> 0.34840671 | L11: =(K11-E11)/E11 -> -0.0056886067 | M11: 491 | N11: =J11/1000 -> 2.045 | O11: 0.018 | P11: =((E11*2*PI())^2-9.8/N11)/2*N11^2*M11 -> 56.457927 | R11: =$A$31*M11*9.8*O11*(N11/O11)^$A$33 -> 66.045476 | S11: =SQRT(2*R11/N11^2/M11+9.8/(N11))/2/PI() -> 0.35073737
A12: 0.0775 | D12: 轴向平动 | E12: 0.4405 | F12: 0.43784 | G12: =(F12-E12)/E12 -> -0.0060385925 | H12: =[1]test_program!$P$18 -> 0.46644714 | I12: =(H12-E12)/E12 -> 0.058903829 | J12: 1410 | K12: =1/2/PI()*SQRT(9.8*1000/J12) -> 0.41958854 | L12: =(K12-E12)/E12 -> -0.047472111 | M12: 491 | N12: =J12/1000 -> 1.41 | O12: 0.018 | Q12: =((E12*2*PI())^2-9.8/N12)/4*N12^2*M12 -> 173.27946 | R12: =$A$41*M12*9.8*O12*(N12/O12)^$A$43 -> 206.30298 | S12: =SQRT(4*R12/N12^2/M12+9.8/(N12))/2/PI() -> 0.44437367
A13: l2 | D13: 平面转动 | E13: 0.69567 | F13: 0.5075 | G13: =(F13-E13)/E13 -> -0.27048744 | H13: =SQRT(H12^2*529/(256.85+1.62*60.5)*0.9^2) -> 0.51255946 | I13: =(H13-E13)/E13 -> -0.26321466 | K13: =SQRT(K12^2*529/(256.85+1.62*60.5)*0.9^2) -> 0.46106848 | L13: =(K13-E13)/E13 -> -0.33723104 | M13: 491
A14: 100.4752
A16: m(kg)_axial
A17: -156.5354
A18: l(m)_axial
A19: 4200.5457
A20: c_axial
A21: 30658.237
A22: ml
A23: -11.1247
A24: m2
A25: 0.202
A26: l2
A27: 198.2246
A29: RADIAL
A30: A
A31: 0.0011244
A32: B
A33: 1.3775
A39: AXIAL
A40: A
A41: 0.076247
A42: B
A43: 0.7892

Sheet help
A1: TB_07+07_MidTop_AA
A2: TB_07+07_MidTop_AR
A3: TB_07+07_MidTop_RA
A4: TB_07+07_MidTop_RR | G4: Working Condition | H4: Radial Translation | I4: Axial Translation | J4: Plane Rotation | L4: 0.6259
A5: TB_07+07_Mid_AA | E5: Single Rod | F5: 07 | G5: TB_07_A | H5: =OFFSET(TB!$E$2,(ROW(TB!E2)-2)*3,0) -> 0.4682 | I5: =OFFSET(TB!$E$3,(ROW(TB!F2)-2)*3,0) -> 0.6099 | J5: =OFFSET(TB!$E$4,(ROW(TB!G2)-2)*3,0) -> 0.6965 | L5: 0.6861
A6: TB_07+07_Mid_AR | G6: TB_07_R | H6: =OFFSET(TB!$E$2,(ROW(TB!E3)-2)*3,0) -> 0.4677 | I6: =OFFSET(TB!$E$3,(ROW(TB!F3)-2)*3,0) -> 0.6095 | J6: =OFFSET(TB!$E$4,(ROW(TB!G3)-2)*3,0) -> 0.6962 | L6: 0.9048
A7: TB_07+07_Mid_RA | F7: 13 | G7: TB_13_A | H7: =OFFSET(TB!$E$2,(ROW(TB!E4)-2)*3,0) -> 0.3691 | I7: =OFFSET(TB!$E$3,(ROW(TB!F4)-2)*3,0) -> 0.4457 | J7: =OFFSET(TB!$E$4,(ROW(TB!G4)-2)*3,0) -> 0.4848 | L7: 0.6267
A8: TB_07+07_Mid_RR | G8: TB_13_R | H8: =OFFSET(TB!$E$2,(ROW(TB!E5)-2)*3,0) -> 0.3704 | I8: =OFFSET(TB!$E$3,(ROW(TB!F5)-2)*3,0) -> 0.4496 | J8: =OFFSET(TB!$E$4,(ROW(TB!G5)-2)*3,0) -> 0.485 | L8: 0.6965
A9: TB_07+13_MidTop_AA | E9: Top | F9: 07 | G9: TB_07_Top_A | H9: =OFFSET(TB!$E$2,(ROW(TB!E6)-2)*3,0) -> 0.4256 | I9: =OFFSET(TB!$E$3,(ROW(TB!F6)-2)*3,0) -> 0.5628 | J9: =OFFSET(TB!$E$4,(ROW(TB!G6)-2)*3,0) -> 0.599 | L9: 0.9046
A10: TB_07+13_MidTop_AR | G10: TB_07_Top_R | H10: =OFFSET(TB!$E$2,(ROW(TB!E7)-2)*3,0) -> 0.4224 | I10: =OFFSET(TB!$E$3,(ROW(TB!F7)-2)*3,0) -> 0.5294 | J10: =OFFSET(TB!$E$4,(ROW(TB!G7)-2)*3,0) -> 0.5712 | L10: 0.3934
A11: TB_07+13_MidTop_RA | F11: 13 | G11: TB_13_Top_A | H11: =OFFSET(TB!$E$2,(ROW(TB!E8)-2)*3,0) -> 0.3517 | I11: =OFFSET(TB!$E$3,(ROW(TB!F8)-2)*3,0) -> 0.4026 | J11: =OFFSET(TB!$E$4,(ROW(TB!G8)-2)*3,0) -> 0.4517 | L11: 0.4574
A12: TB_07+13_MidTop_RR | G12: TB_13_Top_R | H12: =OFFSET(TB!$E$2,(ROW(TB!E9)-2)*3,0) -> 0.352 | I12: =OFFSET(TB!$E$3,(ROW(TB!F9)-2)*3,0) -> 0.4072 | J12: =OFFSET(TB!$E$4,(ROW(TB!G9)-2)*3,0) -> 0.454 | L12: 0.7392
A13: TB_07+13_Mid_AA | E13: Mid | F13: 07+07 | G13: TB_07+07_Mid_AA | H13: =OFFSET(TB!$E$2,(ROW(TB!E10)-2)*3,0) -> 0.334 | I13: =OFFSET(TB!$E$3,(ROW(TB!F10)-2)*3,0) -> 0.3815 | J13: =OFFSET(TB!$E$4,(ROW(TB!G10)-2)*3,0) -> 0.43 | L13: 0.377
A14: TB_07+13_Mid_AR | G14: TB_07+07_Mid_AR | H14: =OFFSET(TB!$E$2,(ROW(TB!E11)-2)*3,0) -> 0.3334 | I14: =OFFSET(TB!$E$3,(ROW(TB!F11)-2)*3,0) -> 0.3833 | J14: =OFFSET(TB!$E$4,(ROW(TB!G11)-2)*3,0) -> 0.4297 | L14: 0.461
A15: TB_07+13_Mid_RA | G15: TB_07+07_Mid_RA | H15: =OFFSET(TB!$E$2,(ROW(TB!E12)-2)*3,0) -> 0.337 | I15: =OFFSET(TB!$E$3,(ROW(TB!F12)-2)*3,0) -> 0.3872 | J15: =OFFSET(TB!$E$4,(ROW(TB!G12)-2)*3,0) -> 0.432 | L15: 0.7438
A16: TB_07+13_Mid_RR | G16: TB_07+07_Mid_RR | H16: =OFFSET(TB!$E$2,(ROW(TB!E13)-2)*3,0) -> 0.3361 | I16: =OFFSET(TB!$E$3,(ROW(TB!F13)-2)*3,0) -> 0.3868 | J16: =OFFSET(TB!$E$4,(ROW(TB!G13)-2)*3,0) -> 0.4266 | L16: 0.4256
A17: TB_07_R | F17: 07+13 | G17: TB_07+13_Mid_AA | H17: =OFFSET(TB!$E$2,(ROW(TB!E14)-2)*3,0) -> 0.2953 | I17: =OFFSET(TB!$E$3,(ROW(TB!F14)-2)*3,0) -> 0.3268 | J17: =OFFSET(TB!$E$4,(ROW(TB!G14)-2)*3,0) -> 0.3621 | L17: 0.4605
A18: TB_07_Top_A | G18: TB_07+13_Mid_AR | H18: =OFFSET(TB!$E$2,(ROW(TB!E15)-2)*3,0) -> 0.2968 | I18: =OFFSET(TB!$E$3,(ROW(TB!F15)-2)*3,0) -> 0.328 | J18: =OFFSET(TB!$E$4,(ROW(TB!G15)-2)*3,0) -> 0.3621 | L18: 0.5688
A19: TB_07_Top_R | G19: TB_07+13_Mid_RA | H19: =OFFSET(TB!$E$2,(ROW(TB!E16)-2)*3,0) -> 0.3009 | I19: =OFFSET(TB!$E$3,(ROW(TB!F16)-2)*3,0) -> 0.3192 | J19: =OFFSET(TB!$E$4,(ROW(TB!G16)-2)*3,0) -> 0.374 | L19: 0.4224
A20: TB_13+07_MidTop_AA | G20: TB_07+13_Mid_RR | H20: =OFFSET(TB!$E$2,(ROW(TB!E17)-2)*3,0) -> 0.2989 | I20: =OFFSET(TB!$E$3,(ROW(TB!F17)-2)*3,0) -> 0.3303 | J20: =OFFSET(TB!$E$4,(ROW(TB!G17)-2)*3,0) -> 0.3593 | L20: 0.4616
A21: TB_13+07_MidTop_AR | F21: 13+07 | G21: TB_13+07_Mid_AA | H21: =OFFSET(TB!$E$2,(ROW(TB!E18)-2)*3,0) -> 0.2993 | I21: =OFFSET(TB!$E$3,(ROW(TB!F18)-2)*3,0) -> 0.3263 | J21: =OFFSET(TB!$E$4,(ROW(TB!G18)-2)*3,0) -> 0.3607 | L21: 0.5294
A22: TB_13+07_MidTop_RA | G22: TB_13+07_Mid_AR | H22: =OFFSET(TB!$E$2,(ROW(TB!E19)-2)*3,0) -> 0.2963 | I22: =OFFSET(TB!$E$3,(ROW(TB!F19)-2)*3,0) -> 0.3272 | J22: =OFFSET(TB!$E$4,(ROW(TB!G19)-2)*3,0) -> 0.3736 | L22: 0.3517
A23: TB_13+07_MidTop_RR | G23: TB_13+07_Mid_RA | H23: =OFFSET(TB!$E$2,(ROW(TB!E20)-2)*3,0) -> 0.2981 | I23: =OFFSET(TB!$E$3,(ROW(TB!F20)-2)*3,0) -> 0.3356 | J23: =OFFSET(TB!$E$4,(ROW(TB!G20)-2)*3,0) -> 0.3673 | L23: 0.3771
A24: TB_13+07_Mid_AA | G24: TB_13+07_Mid_RR | H24: =OFFSET(TB!$E$2,(ROW(TB!E21)-2)*3,0) -> 0.2972 | I24: =OFFSET(TB!$E$3,(ROW(TB!F21)-2)*3,0) -> 0.3305 | J24: =OFFSET(TB!$E$4,(ROW(TB!G21)-2)*3,0) -> 0.3714 | L24: 0.4314
A25: TB_13+07_Mid_AR | E25: MidTop | F25: 07+07 | G25: TB_07+07_MidTop_AA | H25: =OFFSET(TB!$E$2,(ROW(TB!E22)-2)*3,0) -> 0.3198 | I25: =OFFSET(TB!$E$3,(ROW(TB!F22)-2)*3,0) -> 0.3652 | J25: =OFFSET(TB!$E$4,(ROW(TB!G22)-2)*3,0) -> 0.4024 | L25: 0.352
A26: TB_13+07_Mid_RA | G26: TB_07+07_MidTop_AR | H26: =OFFSET(TB!$E$2,(ROW(TB!E23)-2)*3,0) -> 0.3203 | I26: =OFFSET(TB!$E$3,(ROW(TB!F23)-2)*3,0) -> 0.3594 | J26: =OFFSET(TB!$E$4,(ROW(TB!G23)-2)*3,0) -> 0.4087 | L26: 0.3792
A27: TB_13+07_Mid_RR | G27: TB_07+07_MidTop_RA | H27: =OFFSET(TB!$E$2,(ROW(TB!E24)-2)*3,0) -> 0.3213 | I27: =OFFSET(TB!$E$3,(ROW(TB!F24)-2)*3,0) -> 0.3711 | J27: =OFFSET(TB!$E$4,(ROW(TB!G24)-2)*3,0) -> 0.4099 | L27: 0.4288
A28: TB_13_A | G28: TB_07+07_MidTop_RR | H28: =OFFSET(TB!$E$2,(ROW(TB!E25)-2)*3,0) -> 0.3216 | I28: =OFFSET(TB!$E$3,(ROW(TB!F25)-2)*3,0) -> 0.3625 | J28: =OFFSET(TB!$E$4,(ROW(TB!G25)-2)*3,0) -> 0.4176 | L28: 0.334
A29: TB_13_R | F29: 07+13 | G29: TB_07+13_MidTop_AA | H29: =OFFSET(TB!$E$2,(ROW(TB!E26)-2)*3,0) -> 0.287 | I29: =OFFSET(TB!$E$3,(ROW(TB!F26)-2)*3,0) -> 0.3159 | J29: =OFFSET(TB!$E$4,(ROW(TB!G26)-2)*3,0) -> 0.3554 | L29: 0.3528
A30: TB_13_Top_A | G30: TB_07+13_MidTop_AR | H30: =OFFSET(TB!$E$2,(ROW(TB!E27)-2)*3,0) -> 0.2869 | I30: =OFFSET(TB!$E$3,(ROW(TB!F27)-2)*3,0) -> 0.3105 | J30: =OFFSET(TB!$E$4,(ROW(TB!G27)-2)*3,0) -> 0.3559 | L30: 0.4031
A31: TB_13_Top_R | G31: TB_07+13_MidTop_RA | H31: =OFFSET(TB!$E$2,(ROW(TB!E28)-2)*3,0) -> 0.2876 | I31: =OFFSET(TB!$E$3,(ROW(TB!F28)-2)*3,0) -> 0.3173 | J31: =OFFSET(TB!$E$4,(ROW(TB!G28)-2)*3,0) -> 0.3565 | L31: 0.3334
G32: TB_07+13_MidTop_RR | H32: =OFFSET(TB!$E$2,(ROW(TB!E29)-2)*3,0) -> 0.287 | I32: =OFFSET(TB!$E$3,(ROW(TB!F29)-2)*3,0) -> 0.3189 | J32: =OFFSET(TB!$E$4,(ROW(TB!G29)-2)*3,0) -> 0.3565 | L32: 0.3502
F33: 13+07 | G33: TB_13+07_MidTop_AA | H33: =OFFSET(TB!$E$2,(ROW(TB!E30)-2)*3,0) -> 0.2879 | I33: =OFFSET(TB!$E$3,(ROW(TB!F30)-2)*3,0) -> 0.3168 | J33: =OFFSET(TB!$E$4,(ROW(TB!G30)-2)*3,0) -> 0.3558 | L33: 0.4102
G34: TB_13+07_MidTop_AR | H34: =OFFSET(TB!$E$2,(ROW(TB!E31)-2)*3,0) -> 0.2868 | I34: =OFFSET(TB!$E$3,(ROW(TB!F31)-2)*3,0) -> 0.3147 | J34: =OFFSET(TB!$E$4,(ROW(TB!G31)-2)*3,0) -> 0.3534 | L34: 0.337
G35: TB_13+07_MidTop_RA | H35: =OFFSET(TB!$E$2,(ROW(TB!E32)-2)*3,0) -> 0.2873 | I35: =OFFSET(TB!$E$3,(ROW(TB!F32)-2)*3,0) -> 0.3168 | J35: =OFFSET(TB!$E$4,(ROW(TB!G32)-2)*3,0) -> 0.3535 | L35: 0.3479
G36: TB_13+07_MidTop_RR | H36: =OFFSET(TB!$E$2,(ROW(TB!E33)-2)*3,0) -> 0.2874 | I36: =OFFSET(TB!$E$3,(ROW(TB!F33)-2)*3,0) -> 0.3133 | J36: =OFFSET(TB!$E$4,(ROW(TB!G33)-2)*3,0) -> 0.3526 | L36: 0.403
L37: 0.3474
L38: 0.3361
L39: 0.4045
L40: 0.2953
...
